Workbook

Sheet Parameter
A1: Name | B1: Wert | C1: Einheit | D1: Kommentar | F1: Inventor: Link, Start Cell A2 (v8, 12.10.2026)
A2: d1_oring | B2: 54 | C2: mm | D2: O-Ring Innendurchmesser, metrisch, 1 mm Schritte | F2: Block lueckenlos A2 bis D41, Zeile 42 leer.
A3: d2_oring | B3: 1.5 | C3: mm | D3: O-Ring Schnurstaerke. ISO-Toleranz ca. +/-0.08 | F3: Keine Zwischenueberschriften. Eine Zeile ohne Wert
A4: t_nut | B4: 1.15 | C4: mm | D4: Nuttiefe GEMESSEN AB GLASUNTERSEITE, nicht ab Steg | F4: bricht den Import sofort ab.
A5: b_nut | B5: 2.1 | C5: mm | D5: Nutbreite
A6: sp_radial | B6: 0.1 | C6: mm | D6: Radialspiel O-Ring zur Nutaussenwand | F6: ZEILEN 2 BIS 29 SIND EINGEFROREN. Sie tragen
A7: sp_steg | B7: 0.15 | C7: mm | D7: Luft Alusteg zu Glas. Ueberlastanschlag, keine Betriebslage | F7: dieselben Namen in derselben Reihenfolge wie v5.
A8: r_kante | B8: 0.25 | C8: mm | D8: Kantenradius in der Nut | F8: Neue Parameter kommen ab Zeile 30 (gruen) dazu.
A9: d_blende | B9: 0.3 | C9: mm | D9: Blendendicke, Molybdaen | F9: Nie umsortieren, nie dazwischen einfuegen, sonst
A10: h_iso_bett | B10: 0.3 | C10: mm | D10: GEAENDERT v7 von 0.35: Bett = Blendendicke, Blende buendig | F10: verliert Inventor die Zuordnung.
A11: h_iso_kragen | B11: 1 | C11: mm | D11: Kragenhoehe des Isolierrings, rundes Fertigungsmass
A12: r_iso_i | B12: 24 | C12: mm | D12: Isolierring innen | F12: Gelb = Eingabe. Schwarz = berechnet.
A13: r_iso_bett | B13: 25 | C13: mm | D13: Bettaussenradius, fuehrt die Blende radial | F13: Nach dem Aendern speichern, Excel schliessen,
A14: r_iso_a | B14: 26 | C14: mm | D14: Isolierring aussen, Ende der Kragenflaeche | F14: dann in Inventor Parameters > Update.
A15: r_glas_eben | B15: 29.5 | C15: mm | D15: Aussenradius des ebenen Glasbodens, aus Glas_Gefaess.stp
A16: r_alu_bohr | B16: 32 | C16: mm | D16: Aufnahmebohrung im Alu-Ring fuer den Glasfuss r 31 | F16: Alle Radien ab Rotationsachse. Nur d1_oring und
A17: r_oring_m | B17: =(B2+B3)/2 -> 27.75 | C17: mm | D17: O-Ring Mittelradius frei. DIESES Mass in Inventor zeichnen | F17: d2_oring sind Durchmesser nach Norm.
A18: r_oring_a | B18: =B2/2+B3 -> 28.5 | C18: mm | D18: O-Ring Aussenradius, frei | F18: Hoehen zaehlen ab Glasunterseite.
A19: r_nut_a | B19: =B18+B6 -> 28.6 | C19: mm | D19: Nut aussen, Dichtflaeche bei Innendruck
A20: r_nut_i | B20: =B19-B5 -> 26.5 | C20: mm | D20: Nut innen | F20: Dichtung in Inventor als KREIS d2_oring bei
A21: b_ell | B21: =B4/2 -> 0.575 | C21: mm | D21: Dichtung verpresst, Halbachse axial | F21: r_oring_m zeichnen und drehen (Revolve).
A22: a_ell | B22: =B3^2/(2*B4) -> 0.97826087 | C22: mm | D22: Dichtung verpresst, Halbachse radial, flaechengleich | F22: Die Ellipse r_ell_m gehoert nur ins COMSOL-Modell.
A23: r_ell_m | B23: =B19-B22 -> 27.621739 | C23: mm | D23: Dichtung verpresst, Mittelradius. NUR fuer COMSOL
A24: t_steg | B24: =B4-B7 -> 1 | C24: mm | D24: Nuttiefe ab Alusteg, das Fertigungsmass | F24: Isoliertasche: h_tasche_iso ab Glasunterseite,
A25: sp_blende | B25: =B10-B9 -> 0 | C25: mm | D25: Blende gegen Kragen. Null heisst buendig | F25: h_tasche_fert ab Anschlagsteg. Letzteres ist das
A26: h_iso_unten | B26: =B11-B10 -> 0.7 | C26: mm | D26: Restdicke des Isolierrings unter der Blende | F26: Zeichnungsmass, weil der Steg eine Flaeche am
A27: s_verpress | B27: =(B3-B4)/B3 -> 0.23333333 | C27: ul | D27: Verpressung im Betrieb | F27: selben Bauteil ist.
A28: s_max | B28: =(B3-B24)/B3 -> 0.33333333 | C28: ul | D28: Verpressung falls der Alusteg faengt
A29: f_kalt | B29: =PI()*B3^2/4/(B5*B4) -> 0.73173742 | C29: ul | D29: Fuellgrad bei 20 Grad C | F29: Blaetter: Auslegung, Anschlaege, Aenderungen.
A30: fw_iso | B30: 0.5 | C30: mm | D30: NEU v7: Einbauhoehe der Feder unter dem Isolierring
A31: h_glas_fuss | B31: 10.2 | C31: mm | D31: NEU v7: Glasfusshoehe Boden bis Fussoberseite. AM TEIL MESSEN
A32: h_alu_steg_rand | B32: 15.45 | C32: mm | D32: NEU v7: Alu, Anschlagsteg bis Taschenrand. Zeichnungsmass
A33: t_tasche | B33: 6.4 | C33: mm | D33: NEU v7: Tasche fuer den oberen GFK-Ring, absichtlich zu tief
A34: t_gfk_ring | B34: 5.9 | C34: mm | D34: NEU v7: Dicke des oberen GFK-Rings
A35: h_gfk_senk | B35: 0.9 | C35: mm | D35: NEU v7: Senkung r 32 unten am oberen GFK-Ring
A36: h_tasche_iso | B36: =B11+B30 -> 1.5 | C36: mm | D36: NEU v7: Isoliertasche ab Glasunterseite, mit Federraum
A37: h_feder_min | B37: =B30-B7 -> 0.35 | C37: mm | D37: NEU v7: Federhoehe wenn das Glas auf dem Steg sitzt
A38: s_scheibe | B38: =(B31-B35)-(B32-B7-B33) -> 0.4 | C38: mm | D38: NEU v7: Passscheibe aus Nennmassen. Vorhersage, nicht Bestellmass
A39: k_scheibe | B39: =B33-B34+B7 -> 0.65 | C39: mm | D39: NEU v7: Montagemessung, Scheibe = k_scheibe minus gemessenes m
A40: luft_rand | B40: =B33-B34-B38 -> 0.1 | C40: mm | D40: NEU v7: Luft GFK-Oberseite zu Taschenrand
...

Sheet Auslegung
A1: Auslegung der unteren Dichtstelle, Ring unten gegen Glasgefaess (v8, 12.10.2026)
A2: ISO 3601-1 O-Ring, ISO 3601-2 Einbauraum, ISO 3601-5 Werkstoff
A4: Waermedehnung
A5: alpha_ffkm | B5: 0.00022 | C5: 1/K | D5: Linearer Ausdehnungskoeffizient FFKM
A6: alpha_alu | B6: 2.36e-05 | C6: 1/K | D6: Linearer Ausdehnungskoeffizient Aluminium
A7: dT_betrieb | B7: 280 | C7: K | D7: Temperaturhub von 20 auf 300 Grad C
A9: f_heiss | B9: =Parameter!B29*(1+3*B5*B7)/(1+3*B6*B7) -> 0.85010992 | C9: ul | D9: Fuellgrad bei Betriebstemperatur
A10: f_heiss_steg | B10: =PI()*Parameter!B3^2/4/(Parameter!B5*Parameter!B24)*(1+3*B5*B7)/(1+3*B6*B7) -> 0.9776264 | C10: ul | D10: Fuellgrad heiss falls der Steg faengt
A12: Kraefte
A13: F_dicht | B13: 265 | C13: N | D13: FFKM 80 Shore A, ca. 15 N je cm Umfang bei 1.5 mm Schnur
A14: F_feder | B14: 3.5 | C14: N | D14: Wellenfeder Oe48.4/51.6, 12 Wellen, 23 N/mm bei 0.15 mm Weg
A15: h_feder_block | B15: 0.15 | C15: mm | D15: Blockmass = Blechdicke der Wellenfeder. Bei anderer Feder anpassen
A17: A_kragen | B17: =PI()*(Parameter!B14^2-Parameter!B13^2) -> 160.22123 | C17: mm2 | D17: Kragenflaeche des Isolierrings
A18: A_blende | B18: =PI()*(Parameter!B13^2-Parameter!B12^2) -> 153.93804 | C18: mm2 | D18: Auflagering der Blende im Bett
A19: p_feder | B19: =B14/MIN(B17,B18) -> 0.02273642 | C19: MPa | D19: Pressung der Feder gegen das Glas, unguenstigster Fall
A21: Pruefungen
A22: Groesse | B22: Wert | C22: Einheit | D22: Soll min | E22: Soll max | F22: Status | G22: Begruendung
A23: Verpressung | B23: =Parameter!B27 -> 0.23333333 | C23: ul | D23: 0.2 | E23: 0.25 | F23: =IF(AND(B23>=D23,B23<=E23),"ok","PRUEFEN") -> ok | G23: Vakuumdichtung ohne Druckunterstuetzung, plus Reserve fuer Druckverformungsrest
A24: Fuellgrad kalt | B24: =Parameter!B29 -> 0.73173742 | C24: ul | D24: 0.6 | E24: 0.75 | F24: =IF(AND(B24>=D24,B24<=E24),"ok","PRUEFEN") -> ok | G24: Niedriger als die ueblichen 0.85, weil FFKM sich bis 300 Grad C um 18 Prozent ausdehnt
A25: Fuellgrad heiss | B25: =B9 -> 0.85010992 | C25: ul | D25: 0.6 | E25: 0.9 | F25: =IF(AND(B25>=D25,B25<=E25),"ok","PRUEFEN") -> ok | G25: Ueber 0.90 ist die Nut hydraulisch zu und der Ring drueckt die Flaechen auseinander
A26: Fuellgrad heiss am Steg | B26: =B10 -> 0.9776264 | C26: ul | D26: 0.6 | E26: 1.05 | F26: =IF(AND(B26>=D26,B26<=E26),"ok","PRUEFEN") -> ok | G26: Am Ueberlastanschlag laeuft die Nut voll. Darf kalt einmal passieren, nicht heiss
A27: Nutbreite / Schnur | B27: =Parameter!B5/Parameter!B3 -> 1.4 | C27: ul | D27: 1.2 | E27: 1.5 | F27: =IF(AND(B27>=D27,B27<=E27),"ok","PRUEFEN") -> ok | G27: Ueblicher Bereich fuer einen axialen Einbauraum
A28: Verpressung Anschlag | B28: =Parameter!B28 -> 0.33333333 | C28: ul | D28: 0.2 | E28: 0.35 | F28: =IF(AND(B28>=D28,B28<=E28),"ok","PRUEFEN") -> ok | G28: Metall gegen Glas. Schuetzt beim Zusammenbau, nicht im Betrieb
A29: Blende buendig | B29: =ABS(Parameter!B25) -> 0 | C29: mm | D29: 0 | E29: 0.05 | F29: =IF(AND(B29>=D29,B29<=E29),"ok","PRUEFEN") -> ok | G29: Bett gleich Blendendicke, dann druckt die Feder Blende und Kragen gemeinsam ans Glas
A30: Innensteg | B30: =Parameter!B20-Parameter!B14 -> 0.5 | C30: mm | D30: 0.45 | E30: 3 | F30: =IF(AND(B30>=D30,B30<=E30),"ok","PRUEFEN") -> ok | G30: Alu zwischen Isoliertasche und Nut. Traegt nur die Nutwand
A31: Aussensteg bis Glasfase | B31: =Parameter!B15-Parameter!B19 -> 0.9 | C31: mm | D31: 0.75 | E31: 3 | F31: =IF(AND(B31>=D31,B31<=E31),"ok","PRUEFEN") -> ok | G31: Hier muss noch ebenes Glas ueber der Nut sein. Mindestens 0.5 mal Schnurstaerke
A32: Alu-Wand bis Bohrung | B32: =Parameter!B16-Parameter!B19 -> 3.4 | C32: mm | D32: 1 | E32: 10 | F32: =IF(AND(B32>=D32,B32<=E32),"ok","PRUEFEN") -> ok | G32: Restwand nach aussen
A33: Passscheibe im Fenster | B33: =Parameter!B38 -> 0.4 | C33: mm | D33: 0.1 | E33: 0.6 | F33: =IF(AND(B33>=D33,B33<=E33),"ok","PRUEFEN") -> ok | G33: Darunter oder darueber muss die Tasche nachgedreht werden
A34: Luft am Taschenrand | B34: =Parameter!B40 -> 0.1 | C34: mm | D34: 0.05 | E34: 1 | F34: =IF(AND(B34>=D34,B34<=E34),"ok","PRUEFEN") -> ok | G34: Der GFK-Ring darf nicht ueber den Alu-Rand stehen und nicht daran anliegen
A35: Federweg ueber Blockmass | B35: =Parameter!B37-B15 -> 0.2 | C35: mm | D35: 0.05 | E35: 1 | F35: =IF(AND(B35>=D35,B35<=E35),"ok","PRUEFEN") -> ok | G35: Die Feder darf auch im Ueberlastfall nicht auf Block gehen, sonst wird sie ein Anschlag
A36: Pressung der Feder | B36: =B19 -> 0.02273642 | C36: MPa | D36: 0 | E36: 0.2 | F36: =IF(AND(B36>=D36,B36<=E36),"ok","PRUEFEN") -> ok | G36: Feder gegen Glas. Weich genug, um die Masskette nicht zu stoeren
A38: Hinweise
A39: O-Ring. Die Wahl ist durch den Platz erzwungen. Mit r_iso_a 26.00 und der Glasfase ab
A40: r 29.50 liegt das Fenster fuer d1_oring zwischen 54.0 und 54.3 mm. Es passt nur 54 x 1.5.
A41: Keine Dehnung einbauen. Die Nut oeffnet nach oben, der Ring faellt hinein.
A42: Rauheit: Dichtflaechen Rz <= 6.3 Mikrometer, Nutboden Rz <= 16.
A44: Passscheibe. NICHT vorher fertigen. Erst trocken zusammenbauen, ohne O-Ring und ohne
A45: Scheibe, Glas auf den Alusteg druecken, dann mit der Tiefenmessschraube ueber den
A46: Alu-Rand messen, wie tief die GFK-Oberseite darunter liegt. Dieses Mass heisst m.
A47: Dann gilt Scheibe = k_scheibe - m. Diese eine Messung erfasst alle fuenf Toleranzen
...

Sheet Anschlaege
A1: Anschlagreihenfolge: wer bestimmt die Glaslage?
A3: Die Glaslage darf von genau einem Bauteil bestimmt werden. Liegen zwei starre
A4: Anschlaege auf derselben Hoehe, entscheidet die Toleranz, welcher traegt, und der
A5: andere tut nichts. Deshalb diese Reihenfolge mit Abstand dazwischen.
A7: Anschlag | B7: ab Glasunterseite | C7: Spalt t | D7: Verpressung | E7: Rolle
A8: Oberer GFK-Ring auf Passscheibe | B8: 0 | C8: =Parameter!B4 -> 1.15 | D8: =Parameter!B27 -> 0.23333333 | E8: AUSLEGUNG. Metall gegen Metall, die Schraubenkraft geht ins Aluminium
A9: Alu-Anschlagsteg gegen Glas | B9: =Parameter!B7 -> 0.15 | C9: =Parameter!B24 -> 1 | D9: =Parameter!B28 -> 0.33333333 | E9: UEBERLAST. Metall gegen Glas, schuetzt beim Zusammenbau. Nut laeuft heiss voll
A10: Isolierring auf Feder | B10: =Parameter!B30 -> 0.5 | C10: - | D10: - | E10: KEIN ANSCHLAG. Die Feder gibt nach und folgt dem Glas in jede Lage
A13: Befund vom 11.10.2026. Mit dem Isolierring auf Kragen 1.00 in einer 1.00 tiefen Tasche
A14: lag seine Oberseite genau auf der Glasunterseite, also auf derselben Hoehe wie der
A15: obere GFK-Ring in seiner Tasche. Zwei starre Anschlaege auf einer Hoehe, und der
A16: Alusteg 0.15 mm darunter war unerreichbar.
A18: Nachgeben kann der Isolierring nicht:
A19: Macor bei 265 N 0.025 um, bei 12 kN 1.12 um, Bruchlast 55.3 kN
A20: GFK senkrecht bei 265 N 0.165 um, bei 12 kN 7.49 um, Bruchlast 64.1 kN
A21: Fuer 0.15 mm Stauchung braeuchte Macor 10 GPa, das Tausendfache seiner Festigkeit.
A22: Ein Luftspalt von 0.10 mm genuegte auch nicht, weil er den Kragen nur auf y 2.60 hebt
A23: und der Steg bei 2.55 sitzt. Noetig waere mehr als sp_steg. Geloest ueber die Feder,
A24: denn ein weiches Element kann grundsaetzlich kein Anschlag sein.
A26: Damit entfiel die Pruefung 'Pressung Isolierring' mit 1.654 MPa aus v5 und v6. Sie
A27: beschrieb einen Lastpfad durch die Keramik, der jetzt absichtlich leer ist.

Sheet Aenderungen
A1: Aenderungsverzeichnis. Zeilennummern sind Teil der Schnittstelle zu Inventor.
A3: Version | B3: Art | C3: Parameter | D3: Was und warum
A4: v5 | B4: Stand | C4: 28 Parameter | D4: Block A2 bis D29. O-Ring 54 x 1.5, Isolierring als Anschlag.
A5: v6 | B5: FEHLER | C5: 18 Parameter | D5: Neue Parameter wurden MITTEN in den Block eingefuegt. Dadurch wechselten 18 von 28 Parametern die Zeile, unter anderem t_steg von 24 auf 30. Inventor verlor die Zuordnung, Modell unbrauchbar. Nicht verwenden.
A6: v7 | B6: Regel | C6: Zeilen 2 bis 29 | D6: Eingefroren auf die v5-Namen in v5-Reihenfolge. Das Bauskript bricht ab, wenn das nicht stimmt. Neues kommt nur ab Zeile 30 dazu, gruen hinterlegt.
A7: v7 | B7: Wert | C7: h_iso_bett | D7: 0.35 auf 0.30. Bett gleich Blendendicke, Blende liegt buendig zum Kragen. Dadurch wird sp_blende null, h_iso_unten 0.70.
A8: v7 | B8: Neu | C8: fw_iso .. h_gfk_senk | D8: Sechs Eingaben in den Zeilen 30 bis 35 fuer Federraum, Glasfusshoehe und die Masse der GFK-Tasche.
A9: v7 | B9: Neu | C9: h_tasche_iso .. luft_rand | D9: Fuenf Rechenwerte in den Zeilen 36 bis 40 fuer Federweg und Passscheibe.
A10: v7 | B10: Entfaellt | C10: Pruefung p_kragen | D10: Pressung Isolierring 1.654 MPa. Der Lastpfad durch die Keramik ist jetzt leer, siehe Blatt Anschlaege.
A11: v7 | B11: Geometrie | C11: Ring unten | D11: Isoliertaschenboden y 1.70 auf 1.20, GFK-Tasche 6.00 auf 6.40.
A12: v7 | B12: Geometrie | C12: GFK-Ring oben | D12: Freimachung fuer die drei M3x16, Kopf soll auf Alu aufliegen.
A13: v7 | B13: Neuteil | C13: Passscheibe | D13: r 32.2 bis 42.4, neun Loecher Durchmesser 4.0 auf r 38, Dicke nach Messung.
A14: v8 | B14: Neu | C14: h_tasche_fert | D14: Zeile 41. Isoliertaschentiefe ab Anschlagsteg, 1.35 mm. h_tasche_iso 1.50 zaehlt ab Glasunterseite und ist keine Flaeche am Alu-Ring, taugt also nicht als Zeichnungsmass. Zeilen 2 bis 40 unveraendert.
... A17: v8 | B17: Festgelegt | C17: Feder | D17: Einlagige Wellenfeder Oe48.4/51.6, Dicke 0.15, 12 Wellen, freie Hoehe 0.65, Arbeitshoehe 0.50, Rate 23 N/mm. Keine Bohrungen im Taschenboden.
