Workbook

Sheet Parameter
A1: Name | B1: Wert | C1: Einheit | D1: Kommentar | E1: Bauteil | G1: Hinweise
A2: d_glas_i | B2: 46 | C2: mm | D2: Glas innen am Boden (Sockelbohrung r 23). Aus Glas_Gefaess.stp | E2: Glas | G2: Inventor: Verwalten > Parameter > Verknuepfen, Startzelle A2
A3: d_glas_eben | B3: 59 | C3: mm | D3: Aussendurchmesser der ebenen Glasbodenflaeche (r 29.5). Aus STEP | E3: Glas | G3: Block lueckenlos A2 bis D242, Zeile 243 bleibt leer.
A4: d_glas_fuss | B4: 62 | C4: mm | D4: Glasfuss aussen. AM TEIL MESSEN, bestimmt die radiale O-Ring-Nut | E4: Glas | G4: Keine Zwischenueberschriften im Block. Eine Zeile ohne
A5: h_glas_fase | B5: 1.5 | C5: mm | D5: Fase 45 Grad am Glasboden, Hoehe = radiale Breite | E5: Glas | G5: Wert bricht den Import ab.
A6: h_glas_fuss | B6: 10.2 | C6: mm | D6: Glasboden bis Fussoberseite. AM TEIL MESSEN, an 4 Stellen | E6: Glas
A7: d_glas_auflage | B7: 54.2 | C7: mm | D7: Fussoberseite innen (r 27.1), hier drueckt der GFK-Ring | E7: Glas | G7: GELB, blaue Zahl = Eingabe. Alles andere wird berechnet.
A8: t_bl | B8: 0.5 | C8: mm | D8: Blendendicke, Molybdaenblech | E8: Blende | G8: Nie umsortieren, nie dazwischen einfuegen. Neue
A9: d_bl | B9: 72 | C9: mm | D9: Blende aussen | E9: Blende | G9: Parameter nur unten anhaengen, ab Zeile 243.
A10: d_bl_feld | B10: 40 | C10: mm | D10: Groesstes Lochfeld. Alle Loecher muessen innerhalb liegen | E10: Blende
A11: d_bl_loch | B11: 6 | C11: mm | D11: Oeffnung der Standardblende, ein Loch mittig | E11: Blende | G11: Nach dem Aendern speichern, Excel schliessen,
A12: d_bl_klemm | B12: 3 | C12: mm | D12: Klemmloecher, 1 mm Spiel um M2 fuer die Waermedehnung | E12: Blende | G12: dann in Inventor Verwalten > Aktualisieren.
A13: t_kr | B13: 1.5 | C13: mm | D13: Klemmringdicke = einziges Material hinter der Blende | E13: Klemmring
A14: d_kr_i | B14: =$B$2 -> 46 | C14: mm | D14: Klemmring innen, buendig mit der Glasbohrung | E14: Klemmring | G14: Durchmesser heissen d_, Radien r_, Hoehen h_ oder z_,
A15: d_kr_a | B15: =$B$9 -> 72 | C15: mm | D15: Klemmring aussen = Blende aussen | E15: Klemmring | G15: Dicken t_, Breiten b_, Spiele sp_, Winkel w_, Anzahl n_.
A16: b_kr_lasche | B16: 7 | C16: mm | D16: Breite der Kontaktlasche | E16: Klemmring | G16: Alle z-Werte zaehlen ab der Blendenunterseite (z=0),
A17: r_kr_lasche | B17: 39 | C17: mm | D17: Lasche reicht bis zu diesem RADIUS | E17: Klemmring | G17: positiv Richtung Glas.
A18: b_kr_schlitz | B18: 1 | C18: mm | D18: Radialer Schlitz gegen Ringstrom, Fraeser Oe1. GEAENDERT v5d: vorher 0,5 (nur Laser) | E18: Klemmring
A19: r_kontakt | B19: 37 | C19: mm | D19: RADIUS von Kontaktbolzen, Laschengewinde, Huelsenbohrungen | E19: Winkel | G19: Diese Datei gehoert zum NEUEN Aufbau (Version 5 der
A20: w_kontakt | B20: 20 | C20: deg | D20: Winkellage Kontaktbolzen ab X-Achse | E20: Winkel | G20: Blendenaufnahme). Die alte RFN_Dichtung_Parameter.xlsx
A21: w_schlitz | B21: =$B$20+180 -> 200 | C21: deg | D21: Schlitz im Klemmring, gegenueber der Lasche | E21: Winkel | G21: bleibt mit Ring_unten_3 verknuepft und wird nicht mehr
A22: w_m2 | B22: 50 | C22: deg | D22: Winkellage der ersten M2-Klemmschraube | E22: Winkel | G22: geaendert.
A23: w_m25 | B23: 100 | C23: deg | D23: Winkellage der ersten M2.5-Traegerschraube | E23: Winkel
A24: w_m3 | B24: 0 | C24: deg | D24: Winkellage der ersten M3-Federschraube | E24: Winkel | G24: Blaetter: Pruefungen, Auslegung, Inventor_Anleitung,
A25: w_bef | B25: 60 | C25: deg | D25: Winkellage der ersten M2-Befestigungsschraube | E25: Winkel | G25: Baugruppe, Aenderungen.
A26: w_stift | B26: 140 | C26: deg | D26: Winkellage des Passstifts | E26: Winkel
A27: w_senk | B27: 90 | C27: deg | D27: Senkwinkel aller Senkschrauben | E27: Winkel
A28: d_lk_m2 | B28: 67 | C28: mm | D28: Lochkreis M2 Klemmschrauben (Klemmring, Blende, Traeger) | E28: Lochkreise
A29: n_m2 | B29: 6 | C29: ul | D29: Anzahl M2 Klemmschrauben | E29: Lochkreise
A30: d_lk_m25 | B30: 76 | C30: mm | D30: Lochkreis M2.5 Traeger an Stahlring. GEAENDERT v5: vorher 72, jetzt neben der Tasche und durchgebohrt | E30: Lochkreise
A31: n_m25 | B31: 3 | C31: ul | D31: Anzahl M2.5 Traegerschrauben | E31: Lochkreise
A32: d_lk_m3 | B32: 76 | C32: mm | D32: Lochkreis M3 Federschrauben (Stahlring, GFK-Ring oben) | E32: Lochkreise
A33: n_m3 | B33: 9 | C33: ul | D33: Anzahl M3 Federschrauben | E33: Lochkreise
A34: d_lk_bef | B34: 84 | C34: mm | D34: Lochkreis M2 Befestigung und Passstift (Stahlring, Frontplatte) | E34: Lochkreise
A35: n_bef | B35: 3 | C35: ul | D35: Anzahl M2 Befestigungsschrauben | E35: Lochkreise
A36: d_m2_durch | B36: 2.2 | C36: mm | D36: Durchgang M2 | E36: Normteile
A37: d_m2_senk | B37: 4.4 | C37: mm | D37: Senkdurchmesser an der Oberflaeche ISO 14581 M2 = theoretischer Kopf-Ø, Kopf sitzt buendig | E37: Normteile
... A58: d_tr_a | B58: 80 | C58: mm | D58: Traeger aussen, Passung g6 zur Frontplatte | E58: Traeger
A59: d_tr_i | B59: =$B$4+2*$B$142 -> 62.2 | C59: mm | D59: Traeger innen, zentriert den Glasfuss. GEAENDERT v3d: vorher 63 fest | E59: Traeger
A60: h_tr_ueber | B60: 4 | C60: mm | D60: Traeger ueber der Blendenoberseite. GEAENDERT v5: vorher 3,5, Platz fuer den M2-Einsatz | E60: Traeger
...

Sheet Inventor_Anleitung
A1: Inventor-Anleitung: jedes Teil Schritt für Schritt, jede Größe als Parameter
A3: Nr | B3: Befehl / Ort | C3: Was | D3: Parameter / Ausdruck
A5: Vorbereitung, gilt für jedes Bauteil
A6: 1 | B6: Neu > Norm (mm).ipt | C6: Neues Bauteil anlegen.
A7: 2 | B7: Verwalten > Parameter > Verknüpfen | C7: RFN_Aufnahme_Parameter.xlsx wählen, Startzelle A2, Verknüpfen (nicht Einbetten). In jedem Bauteil und auch in der Baugruppe. | D7: Startzelle A2
A8: 3 | B8: Bemaßung eintragen | C8: In jedes Maßfeld den Parameternamen oder einen Ausdruck tippen statt einer Zahl. Inventor zeigt danach fx: vor dem Maß. Steht irgendwo noch eine reine Zahl, ist das ein Fehler. | D8: z. B. d_tr_a oder d_lk_bef/2 - d_m2_kopf/2
A9: 4 | B9: Drehteile | C9: Skizze auf der XY-Ebene. Die Y-Achse ist die Neutralisatorachse, X ist der Radius. Unterseite des Bauteils liegt auf der X-Achse (Y = 0). Unterseite heißt: zur Blende und zum Austritt hin. Beim GFK-Ring oben ist es die Seite zum Glasfuß.
A10: 5 | B10: Mittellinie | C10: Eine Linie auf die Y-Achse legen und im Format-Menü als Mittellinie setzen. Bemaßt man eine Kante gegen die Mittellinie, macht Inventor daraus einen Durchmesser. So lassen sich alle d_-Parameter direkt eintragen, ohne /2. | D10: Mittellinie = Drehachse
A11: 6 | B11: Lochkreise | C11: Skizze auf der Fläche, X-Achse des Bauteils projizieren (Geometrie projizieren > Ursprung). Konstruktionskreis mit dem Lochkreis-Durchmesser um den Ursprung, ein Punkt auf dem Kreis, Konstruktionslinie vom Ursprung zum Punkt, Winkel zur projizierten X-Achse bemaßen. Bohrung auf den Punkt, danach Runde Anordnung um die Y-Achse über 360°. | D11: Kreis d_lk_… Winkel w_… Anzahl n_… Winkel gesamt 360 deg
A12: 7 | B12: Winkelsinn | C12: Alle Winkel von der +X-Achse aus, positiv um die +Y-Achse (Daumen der rechten Hand zeigt zum Glas). Eine Winkelbemaßung in Inventor hat KEIN Vorzeichen: 20° oberhalb und 20° unterhalb der X-Achse sehen gleich aus. Deshalb vor dem Bemaßen auf das Achsenkreuz unten links schauen: Für Winkel zwischen 0° und 180° muss der Punkt auf der Seite liegen, in die Z NICHT zeigt (negatives Z), für 180° bis 360° auf der Seite, in die Z zeigt. Und die Linie muss vom Ursprung aus zur +X-Seite gemessen werden, nicht zur −X-Seite. Kontrolle im fertigen Teil: Ansicht so drehen, dass im Achsenkreuz Y auf dich zeigt und X nach rechts; dann laufen alle Winkel gegen den Uhrzeigersinn, 20° liegt rechts oben. Skizzen auf Unterseiten sind gespiegelt. Nach dem ersten Lochkreis prüfen, dass die Kontaktbohrung (w_kontakt) bei allen Teilen an derselben Stelle liegt. WICHTIG: Lochkreise und Winkel nur auf Ebenen oder Flächen skizzieren, deren Normale nach +Y zeigt (zum Glas), also XZ-Ebene oder Oberseiten. Auf einer Fläche, die nach -Y zeigt (Unterseite, Taschenboden), schaut man von hinten auf die Skizze und alle Winkel werden gespiegelt. Für solche Stellen eine Arbeitsebene parallel zur XZ-Ebene in der passenden Höhe anlegen. Inventor bemaßt Winkel zwischen zwei Linien nur bis 180°. Liegt ein Element über 180°, die Linie in die linke Hälfte zeichnen und Winkel minus 180 eintragen. | D12: w_kontakt als Kontrolle
A13: 8 | B13: Gewindeeinsätze | C13: Als einfache Bohrung mit Einsatz-Bohrdurchmesser und Bohrtiefe. Das Gewinde nicht modellieren, in der Zeichnung als Gewindeeinsatz vermerken. | D13: d_ein_m2 / tb_ein_m2 d_ein_m25 / tb_ein_m25
A14: 9 | B14: Senkungen | C14: Bohrungsbefehl, Typ Senkung. Bohrdurchmesser, Senkdurchmesser und Senkwinkel aus der Tabelle. | D14: d_m2_durch, d_m2_senk, w_senk bzw. d_m25_durch, d_m25_senk, w_senk
A16: Blende | C16: Molybdän, Extrusion. Y = 0 ist die Austrittsseite.
A17: 1 | B17: Skizze auf XZ-Ebene | C17: Kreis um den Ursprung. | D17: Ø d_bl
A18: 2 | B18: Extrusion | C18: Abstand in +Y. | D18: t_bl
A19: 3 | B19: Skizze auf der Oberseite | C19: Lochkreis wie in Vorbereitung Schritt 6. | D19: Kreis d_lk_m2, Winkel w_m2
A20: 4 | B20: Bohrung | C20: Einfache Bohrung, durch alle. | D20: Ø d_bl_klemm
A21: 5 | B21: Runde Anordnung | C21: Bohrung aus Schritt 4. | D21: n_m2, 360 deg
A22: 6 | B22: Bohrung im Ursprung | C22: Öffnung der Standardblende, durch alle. Für andere Lochbilder statt dessen eine eigene Skizze innerhalb eines Konstruktionskreises d_bl_feld. Neue Maße dafür als Parameter unten an die Tabelle anhängen. | D22: Ø d_bl_loch, Lochfeld höchstens Ø d_bl_feld
A23: 7 | B23: Kerbe für den Kontaktbolzen | C23: Skizze auf der Oberseite: Konstruktionslinie Winkel w_kontakt, Länge r_kontakt, Kreis um das Linienende. Extrusion Differenz, durch alle. Jede Blendenvariante braucht diese Kerbe. | D23: Kreis Ø 2*r_bl_kerbe
A24: 8 | B24: Tipp | C24: Für mehrere Blendenvarianten lohnt ein iPart: gleiche Kontur und Kerbe, nur das Lochbild wechselt.
A26: Klemmring | C26: Edelstahl. Ring und Lasche in ZWEI Skizzen und zwei Extrusionen. Y = 0 ist die Austrittsseite.
A27: 1 | B27: Skizze 1 auf XZ-Ebene | C27: Zwei Kreise um den Ursprung. Skizze beenden. | D27: Ø d_kr_a, Ø d_kr_i
A28: 2 | B28: Extrusion | C28: Ringfläche, Richtung +Y. Damit ist der Ring fertig. | D28: t_kr
A29: 3 | B29: Skizze 2 auf XZ-Ebene | C29: Im Browser unter Ursprung: Mittelpunkt und X-Achse mit Rechtsklick > Geometrie projizieren. Ohne projizierte X-Achse lässt sich der Winkel nicht bemaßen.
A30: 4 | B30: Konstruktionslinie | C30: Linie, erster Klick genau auf den Ursprung (gelber Punkt), zweiter Klick schräg nach außen. Format > Konstruktion. Bemaßen: erst X-Achse, dann Linie anklicken = Winkel. Dann die Linie allein anklicken = Länge. | D30: Winkel w_kontakt, Länge r_kr_lasche
A31: 5 | B31: Rechteck, drei Punkte | C31: Grob entlang der Konstruktionslinie in der Nähe ihres Endes aufziehen. Lage egal, die kommt aus den Abhängigkeiten.
A32: 6 | B32: Abhängigkeit Symmetrisch | C32: Eine lange Seite, andere lange Seite, dann die Konstruktionslinie als Symmetrielinie. Rechteck liegt mittig und parallel zur Linie.
A33: 7 | B33: Abhängigkeit Koinzident | C33: Erst den Endpunkt der Konstruktionslinie, dann die äußere kurze Seite.
A34: 8 | B34: Bemaßungen | C34: Abstand der beiden langen Seiten. Dann Ursprungspunkt und innere kurze Seite anklicken = senkrechter Abstand. Die innere Kante liegt im Ringmaterial und verschwindet beim Vereinigen. | D34: b_kr_lasche und d_lk_m2/2
A35: 9 | B35: Skizzenpunkt | C35: Punkt auf die Konstruktionslinie setzen (rastet ein), Abstand vom Ursprung bemaßen. Statusleiste muss jetzt Vollständig bestimmt zeigen, sonst fehlt meist Schritt 7. | D35: r_kontakt
A36: 10 | B36: Extrusion, Vereinigung | C36: Nur das Rechteck als Profil, Richtung +Y. | D36: t_kr
A37: 11 | B37: Skizze 2 freigeben | C37: Browser: Rechtsklick auf Skizze 2 > Skizze freigeben, damit der Punkt für die Bohrung nutzbar bleibt.
A38: 12 | B38: Bohrung, Gewinde | C38: Platzierung Aus Skizze, Punkt aus Schritt 9, ISO-Gewinde M2,5, durch alle. Danach Skizze 2 ausblenden. | D38: M2,5x0,45 (Nenndurchmesser d_kb)
A39: 13 | B39: Skizze 3 für den Schlitz | C39: Wie Schritte 3 bis 8, aber die Konstruktionslinie vom Ursprung nach LINKS zeichnen, in die Gegenrichtung der Lasche. Inventor bemaßt Winkel nur bis 180°, deshalb nicht w_schlitz eintragen, sondern den Winkel zwischen X-Achse und Linie mit w_schlitz - 180. Kontrolle: Schlitz und Lasche liegen sich genau gegenüber. Rechteck symmetrisch, innen und außen eine Schlitzbreite über den Ring. | D39: Winkel w_schlitz - 180 (Linie links), Breite b_kr_schlitz, innere Seite d_kr_i/2 - b_kr_schlitz, äußere Seite d_kr_a/2 + b_kr_schlitz
A40: 14 | B40: Extrusion, Differenz | C40: Durch alle.
A41: 15 | B41: Skizze auf der XZ-Ebene | C41: Die XZ-Ebene liegt genau auf der Unterseite (Y = 0). NICHT auf die Unterseitenfläche selbst skizzieren, sonst wird der Lochkreis gespiegelt. Lochkreis wie Vorbereitung 6. Kontrolle: die erste M2 liegt 30° neben der Lasche, auf der dem Schlitz abgewandten Seite. | D41: Kreis d_lk_m2, Winkel w_m2
A42: 16 | B42: Bohrung, Senkung | C42: Aus Skizze, Senkung an der Skizzenebene (Y = 0), Bohrrichtung +Y, durch alle. Zeigt die Vorschau in die Luft, Richtung umkehren. | D42: d_m2_durch, d_m2_senk, w_senk
A43: 17 | B43: Runde Anordnung | C43: Senkbohrung aus Schritt 16. | D43: n_m2, 360 deg
A44: 18 | B44: NEU v4: Skizze auf der Oberseite | C44: Entlüftungskerben. Die Oberseite liegt an der Blende und zeigt nach +Y, hier wird nichts gespiegelt. Im Browser unter Ursprung Mittelpunkt und X-Achse projizieren. Konstruktionslinie vom Ursprung schräg nach außen, Winkel zur X-Achse und Länge bemaßen. Das Linienende liegt 1 mm außerhalb des Rings. | D44: Winkel w_m2, Länge r_kr_kerbe_a
...

Sheet Baugruppe
A1: Baugruppe: Abhängigkeiten. Parameterdatei auch in der Baugruppe verknüpfen, dann gehen Ausdrücke im Versatzfeld.
A3: Nr | B3: Bauteil | C3: Element | D3: an Bauteil | E3: Element | F3: Abhängigkeit | G3: Versatz / Hinweis
A4: 0 | B4: Vorbereitung | C4: Parameterdatei auch in der Baugruppe verknüpfen (Verwalten > Parameter > Verknüpfen) | D4: — | E4: — | F4: — | G4: Dann gehen Parameternamen im Versatzfeld
A5: 1 | B5: Blende | C5: — | D5: — | E5: — | F5: Fixieren | G5: Erstes Bauteil. Ihr Ursprung ist der Ursprung der Baugruppe, z = 0 = Blendenunterseite
A6: 2 | B6: Klemmring | C6: Y-Achse | D6: Blende | E6: Y-Achse | F6: Passend (Achsen)
A7: 3 | B7: Klemmring | C7: XY-Ebene | D7: Blende | E7: XY-Ebene | F7: Fluchtend, 0 | G7: legt den Winkel fest, alle Bohrungen fluchten automatisch
A8: 4 | B8: Klemmring | C8: XZ-Ebene | D8: Blende | E8: XZ-Ebene | F8: Fluchtend, Versatz | G8: z_kr_unten (= −1,5, Klemmring liegt UNTER der Blende)
A9: 5 | B9: Träger | C9: Y-Achse | D9: Blende | E9: Y-Achse | F9: Passend (Achsen)
A10: 6 | B10: Träger | C10: XY-Ebene | D10: Blende | E10: XY-Ebene | F10: Fluchtend, 0
A11: 7 | B11: Träger | C11: XZ-Ebene | D11: Blende | E11: XZ-Ebene | F11: Fluchtend, Versatz | G11: z_kr_unten (Unterseite bündig mit dem Klemmring)
A12: 8 | B12: Edelstahlring | C12: Y-Achse / XY-Ebene | D12: Blende | E12: Y-Achse / XY-Ebene | F12: Passend / Fluchtend 0
A13: 9 | B13: Edelstahlring | C13: XZ-Ebene | D13: Blende | E13: XZ-Ebene | F13: Fluchtend, Versatz | G13: z_tr_oben (= 4,5)
A14: 10 | B14: GFK-Ring oben | C14: Y-Achse / XY-Ebene | D14: Blende | E14: Y-Achse / XY-Ebene | F14: Passend / Fluchtend 0
A15: 11 | B15: GFK-Ring oben | C15: XZ-Ebene | D15: Blende | E15: XZ-Ebene | F15: Fluchtend, Versatz | G15: z_go_unten (= 10,3)
A16: 12 | B16: Glasgefäß | C16: Z-Achse (seine Achse) | D16: Blende | E16: Y-Achse | F16: Passend (Achsen) | G16: Glas wurde mit Achse Z modelliert
A17: 13 | B17: Glasgefäß | C17: Bodenfläche | D17: Blende | E17: Oberseite | F17: Passend | G17: Hals muss nach +Y zeigen
A18: 14 | B18: Prüfen | C18: Klemmring-Unterseite | D18: Träger | E18: Unterseite | F18: Analyse > Abstand | G18: 0
A19: 15 | B19: Prüfen | C19: Blende-Oberseite | D19: Träger | E19: Taschenboden | F19: Analyse > Abstand | G19: 0
A20: 16 | B20: Prüfen | C20: GFK-Ring Unterseite | D20: Edelstahlring | E20: Oberseite | F20: Analyse > Abstand | G20: sp_go_st = 0,3
A21: 17 | B21: Prüfen | C21: Laschengewinde | D21: Träger | E21: Bolzenbohrung | F21: Achsen fluchten? | G21: sonst XY-Ebene um 180° falsch, Fluchtend statt Passend nehmen
A22: 18 | B22: O-Ring radial | C22: Mittelebene (XZ) | D22: Edelstahlring | E22: XZ-Ebene | F22: Fluchtend, Versatz | G22: z_nut_r + b_nut_r/2
A23: 19 | B23: O-Ring flach | C23: Mittelebene (XZ) | D23: Edelstahlring | E23: XZ-Ebene | F23: Fluchtend, Versatz | G23: t_nut_f - d2_or_f/2
A24: 20 | B24: Keramikhülse | C24: Unterseite / Achse | D24: Träger / Edelstahlring | E24: Oberseite / Hülsenbohrung | F24: Passend | G24: steht auf dem Träger
A25: 21 | B25: Kontaktbolzen | C25: Achse / untere Stirnfläche | D25: Klemmring | E25: Laschengewinde / Unterseite | F25: Passend / Fluchtend | G25: bündig mit der Unterseite
A26: 22 | B26: Muttern, Kabelschuh | C26: Unterseite / Achse | D26: Keramikhülse | E26: Oberseite / Achse | F26: Passend | G26: Mutter, Kabelschuh, Kontermutter
... A45: 41 | B45: Prüfen | C45: Spule, Stäbe, GFK-Ring | D45: — | E45: — | F45: Inspect > Analyze Interference | G45: keine Überschneidung. Inspect > Measure Spule zu Lippe: 1,15. Spule zu Bohrung Ø60,8: 0,3

Sheet Auslegung
A1: Werkstoff- und Federwerte, nicht mit Inventor verknuepft
A3: alpha_st | B3: 1.6e-05 | C3: 1/K | D3: Edelstahl 1.4301, linearer Ausdehnungskoeffizient
A4: alpha_q | B4: 5.5e-07 | C4: 1/K | D4: Quarzglas
A5: alpha_gfk | B5: 1.3e-05 | C5: 1/K | D5: GFK in Faserrichtung (Ringebene)
A6: alpha_mo | B6: 4.8e-06 | C6: 1/K | D6: Molybdaen
A7: dT | B7: 150 | C7: K | D7: Temperaturhub fuer die Pruefungen, von 20 auf 170 Grad C. Nach COMSOL anpassen
A8: c_fe | B8: 8 | C8: N/mm | D8: Federrate der Druckfedern, Platzhalter bis zur Katalogwahl (v5: vorher 12)
A9: dh_glas | B9: 0.1 | C9: mm | D9: Angenommene Abweichung der Glasfusshoehe
A11: Rechenwerte
A12: F_feder | B12: =$B$8*(Parameter!$B$108-Parameter!$B$109) -> 12 | C12: N | D12: Kraft je Feder
A13: F_gesamt | B13: =Parameter!$B$33*B12 -> 108 | C13: N | D13: Summe aller Federn, haelt das Glas auf der Blende
A14: dF_glas | B14: =$B$8*$B$9 -> 0.8 | C14: N | D14: Kraftaenderung je Feder, wenn der Glasfuss um dh_glas abweicht
A15: p_auflage | B15: =B13/(PI()/4*(Parameter!$B$3^2-Parameter!$B$2^2)) -> 0.10073983 | C15: MPa | D15: Flaechenpressung Glasboden auf Blende (Fase vernachlaessigt)
A16: s_or_r_warm | B16: =(Parameter!$B$82*(1+Parameter!$B$172*Parameter!$B$173)-(Parameter!$B$79*(1+$B$3*Parameter!$B$173)-Parameter!$B$4*(1+$B$4*Parameter!$B$173))/2)/(Parameter!$B$82*(1+Parameter!$B$172*Parameter!$B$173)) -> 0.22648916 | C16: ul | D16: Radiale Verpressung warm (dT_or), Ring und Nut dehnen sich aus
A17: f_or_r | B17: =PI()*Parameter!$B$82^2/4/(Parameter!$B$75*(Parameter!$B$79-Parameter!$B$4)/2) -> 0.74735211 | C17: ul | D17: Fuellgrad Radialnut kalt
A18: f_or_r_warm | B18: =B17*(1+Parameter!$B$172*Parameter!$B$173)^3/((Parameter!$B$79*(1+$B$3*Parameter!$B$173)-Parameter!$B$4)/(Parameter!$B$79-Parameter!$B$4)) -> 0.8538668 | C18: ul | D18: Fuellgrad Radialnut warm, FFKM dehnt sich, Nut wird breiter
A19: s_or_f | B19: =(Parameter!$B$86-Parameter!$B$89)/Parameter!$B$86 -> 0.25 | C19: ul | D19: Verpressung Flach-O-Ring
A20: f_or_f | B20: =PI()*Parameter!$B$86^2/4/(Parameter!$B$88*Parameter!$B$89) -> 0.74799825 | C20: ul | D20: Fuellgrad Flachnut
A21: dehn_or_f | B21: =Parameter!$B$87/Parameter!$B$85-1 -> 0.0125 | C21: ul | D21: Dehnung Flach-O-Ring auf dem Nutgrund
A22: dehn_or_r | B22: =Parameter!$B$4/Parameter!$B$81-1 -> 0.0081300813 | C22: ul | D22: Dehnung radialer O-Ring auf dem Glasfuss
A23: dr_mo_gfk | B23: =Parameter!$B$28/2*($B$5-$B$6)*$B$7 -> 0.041205 | C23: mm | D23: Verschiebung GFK gegen Blende am M2-Lochkreis, warm

Sheet Pruefungen
A1: Pruefungen. Jede Zeile muss ok zeigen, sonst die Eingaben im Blatt Parameter aendern.
A3: Pruefung | B3: Wert | C3: Einheit | D3: Soll min | E3: Soll max | F3: Status | G3: Warum
A4: Luft GFK-Ring oben zu Stahl | B4: =Parameter!$B$129 -> 0.3 | C4: mm | D4: 0.15 | E4: 0.5 | F4: =IF(AND(B4>=D4,B4<=E4),"ok","PRÜFEN") -> ok | G4: Darf nie null werden, sonst wird der GFK-Ring zum zweiten Anschlag
A5: Luft im ungünstigsten Fall | B5: =Parameter!$B$129-0.12 -> 0.18 | C5: mm | D5: 0.05 | E5: 0.5 | F5: =IF(AND(B5>=D5,B5<=E5),"ok","PRÜFEN") -> ok | G5: Toleranzkette ±0,12 abgezogen
A6: Radiale Verpressung kalt | B6: =Parameter!$B$84 -> 0.22641509 | C6: ul | D6: 0.15 | E6: 0.25 | F6: =IF(AND(B6>=D6,B6<=E6),"ok","PRÜFEN") -> ok | G6: Statische Radialdichtung
A7: Radiale Verpressung, Glas ganz außermittig, min | B7: =(Parameter!$B$82-((Parameter!$B$79-Parameter!$B$4)/2+Parameter!$B$142))/Parameter!$B$82 -> 0.18867925 | C7: ul | D7: 0.12 | E7: 0.3 | F7: =IF(AND(B7>=D7,B7<=E7),"ok","PRÜFEN") -> ok | G7: Glas liegt auf einer Seite am Träger an
A8: Radiale Verpressung, Glas ganz außermittig, max | B8: =(Parameter!$B$82-((Parameter!$B$79-Parameter!$B$4)/2-Parameter!$B$142))/Parameter!$B$82 -> 0.26415094 | C8: ul | D8: 0.12 | E8: 0.3 | F8: =IF(AND(B8>=D8,B8<=E8),"ok","PRÜFEN") -> ok | G8: Gegenseite
A9: Glas berührt den Stahl nie | B9: =Parameter!$B$143-Parameter!$B$142 -> 0.2 | C9: mm | D9: 0.1 | E9: 1 | F9: =IF(AND(B9>=D9,B9<=E9),"ok","PRÜFEN") -> ok | G9: Träger zentriert, Stahl hat mehr Luft
A10: Radiale Verpressung warm | B10: =Auslegung!$B$16 -> 0.22648916 | C10: ul | D10: 0.12 | E10: 0.3 | F10: =IF(AND(B10>=D10,B10<=E10),"ok","PRÜFEN") -> ok | G10: Bei dT_or: Stahlnut wächst, FFKM-Schnur auch
A11: Füllgrad Radialnut | B11: =Auslegung!$B$17 -> 0.74735211 | C11: ul | D11: 0.6 | E11: 0.85 | F11: =IF(AND(B11>=D11,B11<=E11),"ok","PRÜFEN") -> ok | G11: kalt
A12: Füllgrad Radialnut warm | B12: =Auslegung!$B$18 -> 0.8538668 | C12: ul | D12: 0.6 | E12: 0.9 | F12: =IF(AND(B12>=D12,B12<=E12),"ok","PRÜFEN") -> ok | G12: FFKM dehnt sich stärker als FKM, unter 90 % bleiben
A13: Radialnut über dem Glaszylinder unten | B13: =Parameter!$B$131-(Parameter!$B$8+Parameter!$B$5) -> 3.7 | C13: mm | D13: 0.3 | E13: 20 | F13: =IF(AND(B13>=D13,B13<=E13),"ok","PRÜFEN") -> ok | G13: Nut darf nicht über der Glasfase liegen
A14: Radialnut unter der Fußoberseite | B14: =(Parameter!$B$8+Parameter!$B$6)-Parameter!$B$132 -> 1.4 | C14: mm | D14: 0.3 | E14: 20 | F14: =IF(AND(B14>=D14,B14<=E14),"ok","PRÜFEN") -> ok | G14: Nut muss vollständig am Glaszylinder liegen
A15: Steg Stahl über der Radialnut | B15: =Parameter!$B$73-Parameter!$B$74-Parameter!$B$75 -> 0.7 | C15: mm | D15: 0.5 | E15: 5 | F15: =IF(AND(B15>=D15,B15<=E15),"ok","PRÜFEN") -> ok | G15: Restwand oben
A16: Wand zwischen Flachnut und Radialnut | B16: =Parameter!$B$74-Parameter!$B$89 -> 0.45 | C16: mm | D16: 0.3 | E16: 5 | F16: =IF(AND(B16>=D16,B16<=E16),"ok","PRÜFEN") -> ok | G16: Beide Nuten überlappen radial
A17: Verpressung Flach-O-Ring | B17: =Auslegung!$B$19 -> 0.25 | C17: ul | D17: 0.2 | E17: 0.3 | F17: =IF(AND(B17>=D17,B17<=E17),"ok","PRÜFEN") -> ok | G17: Fuge ist fest verschraubt, Ring auf Block
A18: Füllgrad Flachnut | B18: =Auslegung!$B$20 -> 0.74799825 | C18: ul | D18: 0.6 | E18: 0.85 | F18: =IF(AND(B18>=D18,B18<=E18),"ok","PRÜFEN") -> ok
A19: Dehnung Flach-O-Ring | B19: =Auslegung!$B$21 -> 0.0125 | C19: ul | D19: 0 | E19: 0.03 | F19: =IF(AND(B19>=D19,B19<=E19),"ok","PRÜFEN") -> ok | G19: Hält den Ring beim Montieren in der Nut
A20: Flachnut zur Stahlbohrung | B20: =(Parameter!$B$87-Parameter!$B$71)/2 -> 1.1 | C20: mm | D20: 0.3 | E20: 3 | F20: =IF(AND(B20>=D20,B20<=E20),"ok","PRÜFEN") -> ok | G20: Restwand innen
A21: Flachnut zu den M2,5-Durchgängen | B21: =(Parameter!$B$30-Parameter!$B$39)/2-Parameter!$B$90/2 -> 2.85 | C21: mm | D21: 0.3 | E21: 5 | F21: =IF(AND(B21>=D21,B21<=E21),"ok","PRÜFEN") -> ok | G21: Die Durchgänge müssen außerhalb der Dichtung liegen
A22: M2,5-Senkung zur Radialnut | B22: =(Parameter!$B$30-(Parameter!$B$40-2*(Parameter!$B$73-Parameter!$B$74-Parameter!$B$75)))/2-Parameter!$B$79/2 -> 2.9 | C22: mm | D22: 0.3 | E22: 5 | F22: =IF(AND(B22>=D22,B22<=E22),"ok","PRÜFEN") -> ok | G22: Senkung auf Höhe der Nut-Oberkante gemessen
A23: M2-Senkkopf bündig | B23: =(Parameter!$B$37-2)/2-Parameter!$B$38 -> 0 | C23: mm | D23: 0 | E23: 0.1 | F23: =IF(AND(B23>=D23,B23<=E23),"ok","PRÜFEN") -> ok | G23: Kopf darf nicht aus dem Klemmring stehen
A24: M2,5-Senkkopf bündig | B24: =(Parameter!$B$40-2.5)/2-Parameter!$B$41 -> 0 | C24: mm | D24: 0 | E24: 0.1 | F24: =IF(AND(B24>=D24,B24<=E24),"ok","PRÜFEN") -> ok | G24: Kopf darf nicht über den Stahlring stehen, dort sind nur 0,3 mm Luft zum GFK-Ring
A25: Träger: Einsatz M2 zur Innenbohrung | B25: =(Parameter!$B$28-Parameter!$B$48-Parameter!$B$59)/2 -> 1.35 | C25: mm | D25: 0.8 | E25: 5 | F25: =IF(AND(B25>=D25,B25<=E25),"ok","PRÜFEN") -> ok | G25: GFK-Restwand
A26: Träger: Wand um die Tasche | B26: =(Parameter!$B$58-Parameter!$B$65)/2 -> 3.95 | C26: mm | D26: 1.5 | E26: 6 | F26: =IF(AND(B26>=D26,B26<=E26),"ok","PRÜFEN") -> ok | G26: Isolation Klemmring gegen Frontplatte
A27: Träger: GFK über Einsatz M2 | B27: =Parameter!$B$60-Parameter!$B$69 -> 0.8 | C27: mm | D27: 0.7 | E27: 5 | F27: =IF(AND(B27>=D27,B27<=E27),"ok","PRÜFEN") -> ok | G27: M2 auf Blendenpotential, darüber Stahl
A28: Träger: GFK zwischen Einsatz M2,5 und Tasche | B28: =(Parameter!$B$30-Parameter!$B$167-Parameter!$B$65)/2 -> 0.4 | C28: mm | D28: 0.3 | E28: 5 | F28: =IF(AND(B28>=D28,B28<=E28),"ok","PRÜFEN") -> ok | G28: M2,5 auf Stahlpotential, Klemmring auf Blendenpotential
A29: Träger: GFK zwischen Einsatz M2,5 und Platte | B29: =(Parameter!$B$58-Parameter!$B$30-Parameter!$B$167)/2 -> 0.45 | C29: mm | D29: 0.3 | E29: 5 | F29: =IF(AND(B29>=D29,B29<=E29),"ok","PRÜFEN") -> ok | G29: Platte und Stahl gleiches Potential, nur mechanisch
A30: M2,5 nicht auf dem Lochkreis der M3 | B30: =MIN(MOD(Parameter!$B$23-Parameter!$B$24,360/Parameter!$B$33),360/Parameter!$B$33-MOD(Parameter!$B$23-Parameter!$B$24,360/Parameter!$B$33)) -> 20 | C30: deg | D30: 10 | E30: 20 | F30: =IF(AND(B30>=D30,B30<=E30),"ok","PRÜFEN") -> ok | G30: Beide jetzt auf Ø76
A31: Blende: Steg außen am Klemmloch | B31: =(Parameter!$B$9-Parameter!$B$28-Parameter!$B$12)/2 -> 1 | C31: mm | D31: 0.5 | E31: 5 | F31: =IF(AND(B31>=D31,B31<=E31),"ok","PRÜFEN") -> ok
A32: Blende: Lochfeld in der Glasbohrung | B32: =Parameter!$B$2-Parameter!$B$10 -> 6 | C32: mm | D32: 2 | E32: 40 | F32: =IF(AND(B32>=D32,B32<=E32),"ok","PRÜFEN") -> ok | G32: Kein Loch unter dem Glasboden
A33: Klemmring: Senkkopf im Ring | B33: =Parameter!$B$15/2-(Parameter!$B$28+Parameter!$B$37)/2 -> 0.3 | C33: mm | D33: 0.2 | E33: 5 | F33: =IF(AND(B33>=D33,B33<=E33),"ok","PRÜFEN") -> ok
A34: Klemmring: Senkkopf in der Dicke | B34: =Parameter!$B$13-Parameter!$B$38 -> 0.3 | C34: mm | D34: 0.2 | E34: 2 | F34: =IF(AND(B34>=D34,B34<=E34),"ok","PRÜFEN") -> ok | G34: Kopf bündig versenkt
A35: Einschraubtiefe M2 Klemmung | B35: =Parameter!$B$53-Parameter!$B$13-Parameter!$B$8 -> 2 | C35: mm | D35: 1.5 | E35: 99 | F35: =IF(AND(B35>=D35,B35<=E35),"ok","PRÜFEN") -> ok | G35: Mindestens 0,75 d im Einsatz
A36: M2 Klemmung nicht zu lang | B36: =Parameter!$B$69-(Parameter!$B$53-Parameter!$B$13-Parameter!$B$8) -> 1.2 | C36: mm | D36: 0.2 | E36: 5 | F36: =IF(AND(B36>=D36,B36<=E36),"ok","PRÜFEN") -> ok | G36: Schraube darf nicht auf den Bohrgrund
A37: Einschraubtiefe M2,5 Träger | B37: =Parameter!$B$54-Parameter!$B$73 -> 4.5 | C37: mm | D37: 1.9 | E37: 99 | F37: =IF(AND(B37>=D37,B37<=E37),"ok","PRÜFEN") -> ok
A38: M2,5: Schraubenspitze bleibt im Träger | B38: =Parameter!$B$70-(Parameter!$B$54-Parameter!$B$73) -> 1.5 | C38: mm | D38: 0.2 | E38: 5 | F38: =IF(AND(B38>=D38,B38<=E38),"ok","PRÜFEN") -> ok | G38: Durchgangsloch, Spitze darf hinten nicht herausstehen
A39: M2,5: Einschraubtiefe im Einsatz | B39: =MIN(Parameter!$B$54-Parameter!$B$73,Parameter!$B$51)/2.5 -> 1.8 | C39: ul | D39: 1 | E39: 3 | F39: =IF(AND(B39>=D39,B39<=E39),"ok","PRÜFEN") -> ok | G39: in d, mindestens 1d
A40: Einschraubtiefe M3 Federschraube | B40: =Parameter!$B$55-Parameter!$B$111-Parameter!$B$112 -> 3.9 | C40: mm | D40: 3 | E40: 99 | F40: =IF(AND(B40>=D40,B40<=E40),"ok","PRÜFEN") -> ok | G40: Im Stahl, durchgehendes Gewinde
A41: M3 Federschraube steht nicht unten raus | B41: =Parameter!$B$73-(Parameter!$B$55-Parameter!$B$111-Parameter!$B$112) -> 1.6 | C41: mm | D41: 0.3 | E41: 99 | F41: =IF(AND(B41>=D41,B41<=E41),"ok","PRÜFEN") -> ok | G41: Spitze bleibt im Stahl, berührt den Träger nicht
...

Sheet Aenderungen
A1: Änderungsverzeichnis. Zeilennummern im Blatt Parameter sind Teil der Schnittstelle zu Inventor.
A3: Version | B3: Datum | C3: Art | D3: Was und warum
A4: v1 | B4: 20.10.2026 | C4: Neuanlage | D4: Parameter für die neue untere Aufnahme (Blendenaufnahme Version 5): Blende als Wechselteil, Klemmring, GFK-Träger, Edelstahlring mit radialem und flachem O-Ring, federnder GFK-Ring oben, Frontplatte. 132 Parameter in A2 bis D133.
A5: v1 | B5: 20.10.2026 | C5: Regel | D5: Ab jetzt nie umsortieren und nie dazwischen einfügen. Neue Parameter nur unten anhängen. So ist in v6 der alten Datei die Zuordnung verloren gegangen.
A6: v1 | B6: 20.10.2026 | C6: Abgrenzung | D6: Die alte RFN_Dichtung_Parameter.xlsx (v8) bleibt mit Ring_unten_3 und dem alten Isolierring verknüpft und wird nicht weiter gepflegt.
A7: v1 | B7: 20.10.2026 | C7: Offen | D7: d_glas_fuss und h_glas_fuss sind Nennwerte aus dem STEP. Nach dem Messen eintragen, dann rechnet sich die Radialnut neu. Federwerte sind Platzhalter bis zur Katalogwahl.
A8: v2 | B8: 21.10.2026 | C8: Wert | D8: Kontaktbolzen M3 auf M2,5. r_kontakt 37,5 auf 37,0, r_kr_lasche 39,5 auf 39,0, d_tr_bolzen 3,6 auf 3,0, h_mu 2,4 auf 2,0. Grund: bei M3 blieben nur 0,5 mm Stahl um das Laschengewinde und 0,3 mm GFK zwischen Freistich und Frontplatte. Jetzt 0,75 und 0,8 mm.
A9: v2 | B9: 21.10.2026 | C9: Neu | D9: d_kb in Zeile 134 angehängt. Zeilen 2 bis 133 unverändert, die Verknüpfung in Inventor bleibt bestehen.
A10: v2 | B10: 21.10.2026 | C10: Prüfung | D10: Fünf neue Prüfungen zu Lasche, Freistich, Hülsenbohrung und Bolzendurchgängen.
A11: v2 | B11: 21.10.2026 | C11: Anleitung | D11: Klemmring: Ring und Lasche jetzt in zwei Skizzen und zwei Extrusionen, Lasche über Konstruktionslinie und Symmetrie-Abhängigkeit.
A12: v2b | B12: 21.10.2026 | C12: Anleitung | D12: Schlitz im Klemmring: Winkel über 180° lassen sich in Inventor nicht direkt bemaßen. Linie in die Gegenrichtung zeichnen und w_schlitz - 180 eintragen. Im ersten Modell lag der Schlitz dadurch bei 340° statt 200°.
A13: v2b | B13: 21.10.2026 | C13: Anleitung | D13: Skizzen auf Flächen, die nach -Y zeigen, spiegeln alle Winkel. Im zweiten Klemmring-Modell lagen die M2 dadurch bei 10°, 70° ... statt 50°, 110° ... Klemmring Schritt 15 und Träger Schritte 4 und 6 jetzt auf XZ-Ebene bzw. Arbeitsebene.
A14: v2b | B14: 21.10.2026 | C14: Anleitung | D14: Erster Träger: Freistich bei 160°, Bolzen bei 340°, M2 bei 10°/70° …, weil Winkelmaße in Inventor kein Vorzeichen haben. Vorbereitung 7 enthält jetzt eine Regel über das Achsenkreuz. Außerdem t_tr_tasche von oben statt von unten bemaßt, Taschenboden lag bei 3,5 statt 2,0.
... A56: v9c | B56: 24.10.2026 | C56: Wert | D56: Anschlussnut nicht mehr durch alle: t_go_spule_nut = t_go - (h_go_senk + t_go_lippe) = 4,3 von oben. Nutgrund bündig mit der Lippenoberseite, Lippe geschlossen. Der Anschluss liegt 1,15 über dem Nutgrund wie die unterste Windung über der Lippe.
